Workbook
Name antalTakåsar: Stomme!$L$5
Name antPunkter: [1]UPPSTÄLLNING!$F$6
Name areaGavelspetsar: Stomme!$H$14
Name areaTakåsar: Stomme!$H$15
Name areaVäggliv: Stomme!$H$13
Name bredd: Stomme!$D$6
Name bya: #REF!
Name golvVal: [1]UPPSTÄLLNING!$D$8
Name golvValTjk: [1]UPPSTÄLLNING!$F$8
Name grundVal: [1]UPPSTÄLLNING!$D$6
Name innerArea: Stomme!$D$21
Name inpBredd: Stomme!$C$6
Name inpLängd: Stomme!$C$5
Name inpTakvinkel: Stomme!$B$9
Name inpTjocklek: Stomme!$C$7
Name inpVinkel: Stomme!$C$9
Name inpVägglivsHöjd: Stomme!$C$8
Name invGolvarea: #REF!
Name invTkArea: #REF!
Name invVäggArea: Stomme!$G$15
Name knutUtstick: Stomme!$H$7
Name längd: Stomme!$D$5
Name längdGolvregel: Stomme!$D$22
Name mtrlTotPris: [1]MATERIAL!$F$110
Name rngGolv: [1]!tblGolv[Golv]
Name rngGolvArt: [1]UPPSTÄLLNING!$AQ$15
Name rngGrund: [1]!tblGrund[Grund]
Name rngGrundArt: [1]UPPSTÄLLNING!$AL$15:$AL$16
Name rngTak: [1]!tblTak[Tak]
Name rngTakArt: [1]UPPSTÄLLNING!$AY$15:$AY$22
Name rngVägg: [1]!tblVägg[Vägg]
Name rngVäggArt: [1]UPPSTÄLLNING!$AU$15:$AU$21
Name rngYtskiktGolv: [1]!tblYtskiktGolv[YtskiktGolv]
Name rngYtskiktInnertak: [1]!tblYtskiktInnertak[YtskiktInnertak]
Name rngYtskiktVägg: [1]!tblYtskiktVägg[YtskiktVägg]
Name rngYtskiktYttertak: [1]!tblYtskiktYttertak[YtskiktYttertak]
Name rngYtterTakArt: [1]UPPSTÄLLNING!$BC$18:$BC$30
Name spillfaktor: Stomme!$H$8
Name stBredd: #REF!
Name stLängd: #REF!
Name takArea: Stomme!$H$24
Name takbredd: Stomme!$H$22
Name takfall: Stomme!$H$23
Name takspill: Stomme!$L$7
Name takUtstick: Stomme!$L$6
Name TakVal: [1]UPPSTÄLLNING!$D$12
Name TakValTjk: [1]UPPSTÄLLNING!$F$12
Name takVinkel: Stomme!$D$8
Name TimDeb: [1]Priser!$E$100
Name TimmerHöjd: Stomme!$H$6
Name TimmerTjocklek: Stomme!$H$5
Name totBredd: Stomme!$D$14
Name totLängd: Stomme!$D$13
Name totVäggarea: Stomme!$C$17
Name TsBredd: [1]UPPSTÄLLNING!$L$8
Name TsLängd: [1]UPPSTÄLLNING!$L$6
Name TsMellanvägg: [1]UPPSTÄLLNING!$L$14
Name tTjk: Stomme!$H$5
Name vägglivshöjd: Stomme!$D$7
Name VäggVal: [1]UPPSTÄLLNING!$D$10

Sheet Stomme
B4: Hus dimensioner | D4: (mm) | F4: Timmer | H4: (mm) | J4: Tak | N4: Kostnader/Inköp
B5: Längd | D5: 5000 | F5: Tjocklek | H5: 70 | J5: Ant. takåsar | L5: 3 | N5: Inköp timmer | O5: 68.33
B6: Bredd | D6: 3000 | F6: Höjd | H6: 157 | J6: Takutstick | L6: 370 | N6: Utpris timmer(m2) | O6: 850
B7: Väggliv | D7: 2120 | F7: Knututstick | H7: 140 | J7: Takspill | L7: 0.1 | N7: Arbetstid/m2/h | O7: 2.7
B8: Taklutning | D8: 18 | F8: Spill | H8: 0.05 | N8: Extra kostnader | O8: 2000
B9: Mellanvägg | D9: FALSE | N9: Timdebitering | O9: 550
B12: Husdata | D12: (mm) | F12: Väggareor | J12: Materialåtgång | L12: (lm) | N12: Priser
B13: Tot längd | D13: =längd+(2*knutUtstick) -> 5280 | F13: Area till väggliv | H13: =((2*totLängd*vägglivshöjd)+(2*totBredd*vägglivshöjd))/1000000 -> 36.2944 | J13: Meter timmer | L13: =H18*D15 -> 273.38541 | N13: Inköpskostnad | O13: =(L13*O5)+O8 -> 20680.425
B14: Tot bredd | D14: =bredd+(2*knutUtstick) -> 3280 | F14: Area gavelspets | H14: =2 * ((totBredd/1000)/2 * TAN(RADIANS(takVinkel)) * (totBredd/1000)/2) -> 1.747808 | N14: Utpris | O14: =(O6*H18)+O8 -> 38483.283
B15: Timmer per m2 | D15: =1/TimmerHöjd*1000 -> 6.3694268 | F15: Area takåsar | H15: =((((2*takUtstick)+totLängd)*TimmerHöjd)*antalTakåsar)/1000000 -> 2.83542 | N15: Arbetstid | O15: =H18/O7 -> 15.896855
B16: Gavelhöjd | D16: =(TAN(RADIANS(takVinkel))*totBredd)/2 -> 532.8683 | F16: Spill | H16: =SUM(H13:H15)*(1 + H8)-SUM(H13:H15) -> 2.0438814 | N16: Arbetskostnad | O16: =O15*O9 -> 8743.2704
F17: Mellanvägg | H17: =IF(D9, (D14*D7)+(H14/2), 0)/1000000 -> 0 | N17: Avans | O17: =O14-O13-O16 -> 9059.5875
F18: Total Väggarea | H18: =areaVäggliv+areaGavelspetsar+areaTakåsar+H16+H17 -> 42.921509
N19: Pris inkl moms | O19: =O14*1.25 -> 48104.104
B20: Golvdata | F20: Takdata | H20: (mm / m2)
B21: Innerarea | D21: =((längd-(2*TimmerTjocklek))*((bredd-(2*TimmerTjocklek))/1000000)) -> 13.8996 | F21: Taklängd | H21: =D5 (längd) + 2 * L6 (takUtstick) -> 5740
B22: Längd Golvregel | D22: =bredd-(2*TimmerTjocklek) -> 2860 | F22: Takbredd | H22: =D6 (bredd) + 2 * L6 (takUtstick) -> 3740
B23: Antal golvreglar | D23: =ROUNDUP(((längd-(2*TimmerTjocklek))/0.6)/1000,0)-1 -> 8 | F23: Takfall(en sida) | H23: =(takbredd/2)/COS(RADIANS(D8)) -> 1966.2344
F24: Takarea (total) | H24: =2 * (H23 * H21) / 1000000 -> 22.57237
F25: Takyta med spill | H25: =takArea * (1+takspill) -> 24.829607

Sheet Tidskalkyl
C2: Aktivitet | D2: Enhet | E2: Mängd/m2 | F2: Enhetstid | G2: Mängd | H2: Överskriven | I2: Använd | J2: Tidsåtgång | L2: Antal
C4: GOLV
B6: TRUE | C6: Golvreglar 45x145-220 | D6: lm | E6: 1.67 | F6: 0.2 | G6: =E6*innerArea -> 23.212332 | I6: =IF($B6, IF($H6<>"", $H6, $G6), "") -> 23.212332 | J6: =IF(B6,(I6*F6)/24,"-") -> 0.1934361 | K6: {=_xlfn._xlws.FILTER(J6:J17,B6:B17=TRUE)} -> 0.1934361 | L6: =IF(B6,(längd/1000)/0.6-1,"-") -> 7.3333333 | M6: =IF(B6,"st","") -> st | N6: =IF(B6,"a","") -> a | O6: =IF(B6,bredd-(2*TimmerTjocklek),"") -> 2860 | P6: =IF(B6,"mm","") -> mm
B7: TRUE | C7: Stödregel 45x45 | D7: lm | E7: =2*längdGolvregel/1000 -> 5.72 | F7: 0.06 | G7: =E7 -> 5.72 | I7: =IF($B7, IF($H7<>"", $H7, $G7), "") -> 5.72 | J7: =IF(B7,(I7*F7)/24,"-") -> 0.0143 | K7: 0.0143 | L7: =IF(B7,(IF(Stomme!D9,4,"2")),"-") -> 2 | M7: =IF(B7,"st","") -> st | N7: =IF(B7,"a","") -> a | O7: =IF(B7,bredd-(2*TimmerTjocklek),"") -> 2860 | P7: =IF(B7,"mm","") -> mm
B8: FALSE | C8: Trossbottenbräda 22x95 | D8: m2 | E8: 1.67 | F8: 0.08 | G8: =innerArea*E8 -> 23.212332 | I8: =IF($B8, IF($H8<>"", $H8, $G8), "") | J8: =IF(B8,(I8*F8)/24,"-") -> - | K8: 0.2027025
B9: FALSE | C9: Trossbottenskiva 0,72m2/skiva | D9: m2 | E9: 1.38 | F9: 0.08 | G9: =innerArea*E9 -> 19.181448 | I9: =IF($B9, IF($H9<>"", $H9, $G9), "") | J9: =IF(B9,(I9*F9)/24,"-") -> -
B10: FALSE | C10: Trossbottenpapp vindpapp exkl. klämlist | D10: m2 | E10: 1.67 | F10: 0.08 | G10: =innerArea*E10 -> 23.212332 | I10: =IF($B10, IF($H10<>"", $H10, $G10), "") | J10: =IF(B10,(I10*F10)/24,"-") -> -
B11: FALSE | C11: Klämlist 15x15mm | D11: m2 | E11: 3.34 | F11: 0.04 | G11: =innerArea*E11 -> 46.424664 | I11: =IF($B11, IF($H11<>"", $H11, $G11), "") | J11: =IF(B11,(I11*F11)/24,"-") -> -
B12: FALSE | C12: Isolering skivor | D12: m2 | E12: 0.69 | F12: 0.15 | G12: =innerArea*E12 -> 9.590724 | I12: =IF($B12, IF($H12<>"", $H12, $G12), "") | J12: =IF(B12,(I12*F12)/24,"-") -> -
B13: FALSE | C13: Trägolv 25x165 | D13: m2 | E13: 6.1 | F13: 0.5 | G13: =innerArea*E13 -> 84.78756 | I13: =IF($B13, IF($H13<>"", $H13, $G13), "") | J13: =IF(B13,((I13/E13)*F13)/24,"-") -> -
B14: FALSE | C14: Parkett 14mm klicktyp | D14: m2 | E14: 1 | F14: 0.22 | G14: =innerArea*E14 -> 13.8996 | I14: =IF($B14, IF($H14<>"", $H14, $G14), "") | J14: =IF(B14,(I14*F14)/24,"-") -> -
B15: FALSE | C15: Spånskivegolv 22mm 600x2420 limmat | D15: m2 | E15: 1.44 | F15: 0.21 | G15: =innerArea*E15 -> 20.015424 | I15: =IF($B15, IF($H15<>"", $H15, $G15), "") | J15: =IF(B15,(I15*F15)/24,"-") -> -
B16: TRUE | C16: Trallgolv 120mm 9,52m/m2 | D16: lm | E16: 8.4 | F16: 0.35 | G16: =(innerArea*E16) -> 116.75664 | I16: =IF($B16, IF($H16<>"", $H16, $G16), "") -> 116.75664 | J16: =IF(B16,(I16/E16*F16)/24,"-") -> 0.2027025
B17: FALSE | C17: Trallgolv 145mm 7,56m/m2 | D17: m2 | E17: 7.56 | F17: 0.3 | G17: =(innerArea*E17) -> 105.08098 | I17: =IF($B17, IF($H17<>"", $H17, $G17), "") | J17: =IF(B17,(I17/E17*F17)/24,"-") -> -
G18: Summa tid: | J18: =SUM(K6:K16) -> 0.4104386
C20: VÄGGREGELSTOMME
B21: FALSE | C21: Ytterpanel | D21: m2 | E21: 7.85 | F21: 0.6 | G21: =totVäggarea -> 0 | J21: =(G21*F21)/24 -> 0 | K21: {=_xlfn._xlws.FILTER(J21:J29,B21:B29=TRUE)} -> #VALUE!
B22: FALSE | C22: Spikläkt utsida 34x70 | D22: m2 | E22: 6.25 | F22: 0.13 | G22: =totVäggarea -> 0 | J22: =(G22*F22)/24 -> 0
B23: FALSE | C23: Vindpapp | D23: m2 | E23: 1 | F23: 0.06 | G23: =totVäggarea -> 0 | J23: =(G23*F23)/24 -> 0
B24: FALSE | C24: Utvändig gips | D24: m2 | E24: 1 | F24: 0.2 | G24: =totVäggarea -> 0 | J24: =(G24*F24)/24 -> 0
B25: FALSE | C25: Västkustskiva | D25: m2 | E25: 1 | F25: 0.25 | G25: =totVäggarea -> 0 | J25: =(G25*F25)/24 -> 0
B26: FALSE | C26: Regelstomme 45x145-195 | D26: m2 | E26: 1.67 | F26: 0.22 | G26: =totVäggarea -> 0 | J26: =(G26*F26)/24 -> 0
B27: FALSE | C27: Isolering 145-195 | D27: m2 | E27: 1 | F27: 0.06 | G27: =totVäggarea -> 0 | J27: =(G27*F27)/24 -> 0
B28: FALSE | C28: Ångbroms | D28: m2 | E28: 1 | F28: 0.08 | G28: =invVäggArea -> 0 | J28: =(G28*F28)/24 -> 0
B29: FALSE | C29: Installationsläkt 45x45 | D29: m2 | E29: 1.67 | F29: 0.13 | G29: =invVäggArea -> 0 | J29: =(G29*F29)/24 -> 0
B30: FALSE | C30: Plywood 1200mm 12-15mm | D30: m2 | E30: 3 | J30: =(G30*F30)/24 -> 0
B31: FALSE | C31: Gips 900x2500X | D31: m2 | E31: 2.25 | J31: =(G31*F31)/24 -> 0
B32: FALSE | C32: Träpanel 15x95 | D32: m2 | E32: 11.36 | J32: =(G32*F32)/24 -> 0
B33: FALSE | C33: Träpanel 15x120 | D33: m2 | E33: 9.52 | J33: =(G33*F33)/24 -> 0
B34: FALSE | C34: Träpanel övrig | D34: m2 | J34: =(G34*F34)/24 -> 0
G35: Summa tid: | J35: =SUM(K21:K34) -> #VALUE!
C38: TAK
B39: TRUE | C39: Råspontslucka | D39: st | E39: 1.94 | F39: 0.35 | G39: =CEILING(Stomme!H25/E39,1) -> 13 | H39: 14 | I39: =IF($B39, IF($H39<>"", $H39, $G39), "") -> 14 | J39: =IF(B39,(I39*F39)/24,"-") -> 0.20416667 | K39: =J39 -> 0.20416667
B40: TRUE | C40: Underlagspapp 25x1m | D40: rul | E40: 25 | F40: 2 | G40: =CEILING(Stomme!H25/E40,1) -> 1 | I40: =IF($B40, IF($H40<>"", $H40, $G40), "") -> 1 | J40: =IF(B40,(I40*F40)/24,"-") -> 0.083333333 | K40: =J40 -> 0.083333333
B41: TRUE | C41: Ströläkt 12x50 c/c 0,6 | D41: lm | E41: =ROUNDUP(1/0.5,2) -> 2 | F41: 0.04 | G41: =CEILING(Stomme!H25*E41,1) -> 50 | I41: =IF($B41, IF($H41<>"", $H41, $G41), "") -> 50 | J41: =IF(B41,(I41*F41)/24,"-") -> 0.083333333 | K41: =J41 -> 0.083333333
B42: TRUE | C42: Bärläkt 28x70 c/c 0,5 | D42: lm | E42: =ROUNDUP(1/0.6,2) -> 1.67 | F42: 0.08 | G42: =CEILING(Stomme!H25*E42,1) -> 42 | I42: =IF($B42, IF($H42<>"", $H42, $G42), "") -> 42 | J42: =IF(B42,(I42*F42)/24,"-") -> 0.14 | K42: =J42 -> 0.14
B43: TRUE | C43: Vindskivor 22x145 | D43: lm | E43: 1 | F43: 0.4 | G43: =CEILING((takfall+150)*4,1000)/1000 -> 9 | I43: 18 | J43: =IF(B43,(I43*F43)/24,"-") -> 0.3 | K43: =J43 -> 0.3
B44: TRUE | C44: Takfotsbräda 22x145 | D44: lm | E44: 1 | F44: 0.15 | G44: =CEILING(Stomme!H21*2,1000)/1000 -> 12 | I44: =IF($B44, IF($H44<>"", $H44, $G44), "") -> 12 | J44: =IF(B44,(I44*F44)/24,"-") -> 0.075 | K44: =J44 -> 0.075
B45: TRUE | C45: Vindskiveregel 45x45 | D45: lm | E45: 1 | F45: 0.15 | G45: =CEILING(takfall*4,1000)/1000 -> 8 | I45: =IF($B45, IF($H45<>"", $H45, $G45), "") -> 8 | J45: =IF(B45,(I45*F45)/24,"-") -> 0.05 | K45: =J45 -> 0.05
B46: TRUE | C46: Takplåt | D46: m2 | E46: 1 | F46: 0.25 | G46: =CEILING(Stomme!H24,1) -> 23 | I46: =IF($B46, IF($H46<>"", $H46, $G46), "") -> 23 | J46: =IF(B46,(I46*F46)/24,"-") -> 0.23958333 | K46: =J46 -> 0.23958333 | M46: =CEILING(Stomme!H21/1000,1)*2 -> 12
...

Sheet Plocklista
B3: Plocklista | E3: Projekt: | F3: Ulf Nilsson
B5: Artikel | D5: Mängd | E5: Enhet | F5: Notering
B6: {=_xlfn._xlws.FILTER(Tidskalkyl!C:C, Tidskalkyl!B:B=TRUE, "")} -> Golvreglar 45x145-220 | D6: {=_xlfn._xlws.FILTER(Tidskalkyl!I:I, Tidskalkyl!B:B=TRUE, "")} -> 23.212332 | E6: {=_xlfn._xlws.FILTER(Tidskalkyl!D:D, Tidskalkyl!B:B=TRUE, "")} -> lm | F6: 45x170 impregnerad
B7: Stödregel 45x45 | D7: 5.72 | E7: lm | F7: 45x45 impregnerad
B8: Trallgolv 120mm 9,52m/m2 | D8: 116.75664 | E8: lm
B9: Råspontslucka | D9: 14 | E9: st
B10: Underlagspapp 25x1m | D10: 1 | E10: rul
B11: Ströläkt 12x50 c/c 0,6 | D11: 50 | E11: lm
B12: Bärläkt 28x70 c/c 0,5 | D12: 42 | E12: lm
B13: Vindskivor 22x145 | D13: 18 | E13: lm
B14: Takfotsbräda 22x145 | D14: 12 | E14: lm
B15: Vindskiveregel 45x45 | D15: 8 | E15: lm
B16: Takplåt | D16: 23 | E16: m2 | F16: 12 st 2m TP20
B17: Fotplåt | D17: 8 | E17: st
B18: Vindskiveplåt | D18: 6 | E18: st
B19: Nockplåt | D19: 3 | E19: st
B20: Tätband | D20: 12 | E20: lm
B21: Bärläktsskruv 35mm | D21: 136 | E21: st
B22: överlappsskruv 20mm | D22: 92 | E22: st
B23: Betongsten 400x400x100 | D23: 15 | E23: st

Sheet Sheet1
A6: {=_xlfn._xlws.FILTER(Tidskalkyl!C:C, Tidskalkyl!B:B=TRUE, "")} -> Golvreglar 45x145-220 | B6: {=_xlfn._xlws.FILTER(Tidskalkyl!I:I, Tidskalkyl!B:B=TRUE, "")} -> 23.212332
A7: Stödregel 45x45 | B7: 5.72
A8: Trallgolv 120mm 9,52m/m2 | B8: 116.75664
A9: Råspontslucka | B9: 14
A10: Underlagspapp 25x1m | B10: 1
A11: Ströläkt 12x50 c/c 0,6 | B11: 50
A12: Bärläkt 28x70 c/c 0,5 | B12: 42
A13: Vindskivor 22x145 | B13: 18
A14: Takfotsbräda 22x145 | B14: 12
A15: Vindskiveregel 45x45 | B15: 8
A16: Takplåt | B16: 23
A17: Fotplåt | B17: 8
A18: Vindskiveplåt | B18: 6
... A23: Betongsten 400x400x100 | B23: 15

Sheet Tidrapport
A5: Datum | B5: Aktivitet | C5: Tid | D5: Enhet | E5: Enhetstid | F5: Mängd | G5: Överskriven | H5: Använd | I5: Tidsåtgång
A6: 250828 | B6: Grundstenar, 1a varv | C6: 1.5 | D6: tim
A7: 250829 | B7: Golvbjälkar | C7: 3 | D7: tim
A8: 250830 | B8: Trallgolv och bärlina | C8: 2 | D8: tim

Sheet Prislista
A1: 100

Sheet Fakturor
A5: Företag | B5: Material | C5: Antal | D5: Enhet | E5: st pris | F5: Totalt | G5: Kalkulerat | H5: Använd | I5: Tidsåtgång
A6: KBYGG | B6: BETONGPLATTA 40X40X10 38,4KG | C6: 15 | D6: st | E6: 126 | F6: =E6*C6 -> 1890
A7: KBYGG | B7: REGEL IMP AB 45X95X4800 C24 | C7: 1 | D7: st | E7: 107.68

Sheet Uppföljning
A5: Datum | B5: Aktivitet | C5: Tid | D5: Enhet | E5: Enhetstid | F5: Mängd | G5: Överskriven | H5: Använd | I5: Tidsåtgång
